<?xml version="1.0"?>
<robot name="ball_and_string">

  <!-- Ball link -->
  <link name="ball">
    <visual>
      <geometry>
        <sphere radius="0.05"/>
      </geometry>
      <material name="black">
        <color rgba="0.0 0.0 0.0 1.0"/>
      </material>
    </visual>
    <collision>
      <geometry>
        <sphere radius="0.05"/>
      </geometry>
    </collision>
    <inertial>
      <mass value="0.1"/>
      <inertia ixx="0.000001" ixy="0.0" ixz="0.0" iyy="0.000001" iyz="0.0" izz="0.000001"/>
    </inertial>
  </link>

  <!-- Anchor link -->
  <link name="anchor">
    <visual>
      <geometry>
        <box size="0.03 0.03 0.03"/>
      </geometry>
      <material name="blue">
        <color rgba="0.0 0.0 1.0 1.0"/>
      </material>
    </visual>
    <inertial>
      <mass value="0.001"/>
      <inertia ixx="0.000001" ixy="0.0" ixz="0.0" iyy="0.000001" iyz="0.0" izz="0.000001"/>
    </inertial>
  </link>

  <!-- Sliding joint -->
  <joint name="ball_to_base" type="prismatic">
    <parent link="ball"/>
    <child link="anchor"/>
    <!-- default string length -->
    <origin xyz="0 0 0.5" rpy="0 0 0"/>
    <!-- maximum string length -->
    <limit lower="-0.5" upper="1.0" effort="0.0"/>
    <axis xyz="0 0 1"/>
  </joint>

</robot>
