<?xml version="1.0" ?>
<!-- =================================================================================== -->
<!-- |    This document was autogenerated by xacro from car.urdf.xacro                 | -->
<!-- |    EDITING THIS FILE BY HAND IS NOT RECOMMENDED                                 | -->
<!-- =================================================================================== -->
<robot name="navgroup" xmlns:body="http://playerstage.sourceforge.net/gazebo/xmlschema/#body" xmlns:controller="http://playerstage.sourceforge.net/gazebo/xmlschema/#controller" xmlns:gazebo="http://playerstage.sourceforge.net/gazebo/xmlschema/#gz" xmlns:geom="http://playerstage.sourceforge.net/gazebo/xmlschema/#geom" xmlns:interface="http://playerstage.sourceforge.net/gazebo/xmlschema/#interface" xmlns:joint="http://playerstage.sourceforge.net/gazebo/xmlschema/#joint" xmlns:model="http://playerstage.sourceforge.net/gazebo/xmlschema/#model" xmlns:physics="http://playerstage.sourceforge.net/gazebo/xmlschema/#physics" xmlns:rendering="http://playerstage.sourceforge.net/gazebo/xmlschema/#rendering" xmlns:sensor="http://playerstage.sourceforge.net/gazebo/xmlschema/#sensor" xmlns:xacro="http://www.ros.org/wiki/xacro">
  <!-- Physical Constant Macros -->
  <!-- Dimension Macros -->
  <!-- Physical Material Macros -->
  <material name="Red">
    <color rgba="1.0 0 0 1.0"/>
  </material>
  <material name="Green">
    <color rgba="0 1.0 0 1.0"/>
  </material>
  <material name="Blue">
    <color rgba="0 0 1.0 0.5"/>
  </material>
  <material name="Black">
    <color rgba="0 0 0 1.0"/>
  </material>
  <material name="Aqua">
    <color rgba="0 255 255 1.0"/>
  </material>
  <!-- Main body -->
  <link name="base_link">
    <inertial>
      <mass value="0.2"/>
      <origin xyz="0 0 0"/>
      <inertia ixx="0.2" ixy="0.0" ixz="0.0" iyy="0.2" iyz="0.0" izz="0.2"/>
    </inertial>
    <visual>
      <origin rpy="0 0 0" xyz="0 0 0"/>
      <geometry>
        <box size="0.3 0.15 0.1"/>
      </geometry>
      <material name="Red"/>
    </visual>
    <collision>
      <origin rpy="0 0 0" xyz="0 0 0"/>
      <geometry>
        <box size="0.3 0.15 0.1"/>
      </geometry>
    </collision>
  </link>
  <gazebo reference="base_link">
    <material>Gazebo/Red</material>
  </gazebo>
  <!-- Front link of Ackermann -->
  <!-- Joins to the Car body -->
  <joint name="front_joint" type="fixed">
    <parent link="base_link"/>
    <child link="front_link"/>
    <origin xyz="0.16 0.0 -0.1"/>
  </joint>
  <link name="front_link">
    <inertial>
      <mass value="0.01"/>
      <origin xyz="0 0 0"/>
      <inertia ixx="0.01" ixy="0.0" ixz="0.0" iyy="0.01" iyz="0.0" izz="0.01"/>
    </inertial>
    <visual>
      <geometry>
        <box size="0.015 0.15 0.005"/>
      </geometry>
      <material name="Aqua"/>
    </visual>
    <collision>
      <geometry>
        <box size="0.015 0.15 0.005"/>
      </geometry>
    </collision>
  </link>
  <gazebo reference="front_link">
    <material>Gazebo/Green</material>
  </gazebo>
  <!-- a link aligned with the steer direction -->
  <joint name="steer_joint" type="revolute">
    <limit effort="100" lower="-0.5" upper="0.5" velocity="10"/>
    <axis xyz="0 0 1"/>
    <parent link="front_link"/>
    <child link="steer_link"/>
    <origin rpy="0 0 0" xyz="0.0 0.0 0.0"/>
  </joint>
  <link name="steer_link">
    <inertial>
      <mass value="0.01"/>
      <origin xyz="0 0 0"/>
      <inertia ixx="0.01" ixy="0.0" ixz="0.0" iyy="0.01" iyz="0.0" izz="0.01"/>
    </inertial>
    <visual>
      <origin xyz="-0.02 0 0"/>
      <geometry>
        <box size="0.03 0.01995 0.005"/>
      </geometry>
      <material name="Green"/>
    </visual>
    <collision>
      <origin xyz="0.02 0 0"/>
      <geometry>
        <box size="0.03 0.01995 0.005"/>
      </geometry>
    </collision>
  </link>
  <gazebo reference="steer_link">
    <material>Gazebo/Green</material>
  </gazebo>
  <!-- the left Ackermann bar -->
  <joint name="front_left_bar_joint" type="revolute">
    <limit effort="100" lower="-0.5" upper="0.5" velocity="10"/>
    <axis xyz="0 0 1"/>
    <parent link="front_link"/>
    <child link="front_left_bar_link"/>
    <origin rpy="0 0 0" xyz="0.0 0.06 0.0"/>
  </joint>
  <link name="front_left_bar_link">
    <inertial>
      <mass value="0.01"/>
      <origin xyz="0 0 0"/>
      <inertia ixx="0.01" ixy="0.0" ixz="0.0" iyy="0.01" iyz="0.0" izz="0.01"/>
    </inertial>
    <visual>
      <origin xyz="-0.02 0 0"/>
      <geometry>
        <box size="0.03 0.01995 0.005"/>
      </geometry>
      <material name="Green"/>
    </visual>
    <collision>
      <origin xyz="-0.02 0 0"/>
      <geometry>
        <box size="0.03 0.01995 0.005"/>
      </geometry>
    </collision>
  </link>
  <gazebo reference="front_left_bar_link">
    <material>Gazebo/Green</material>
  </gazebo>
  <!-- the right Ackermann bar -->
  <joint name="front_right_bar_joint" type="revolute">
    <limit effort="100" lower="-0.5" upper="0.5" velocity="10"/>
    <axis xyz="0 0 1"/>
    <parent link="front_link"/>
    <child link="front_right_bar_link"/>
    <origin rpy="0 0 0" xyz="0.0 -0.06 0.0"/>
  </joint>
  <link name="front_right_bar_link">
    <inertial>
      <mass value="0.01"/>
      <origin xyz="0 0 0"/>
      <inertia ixx="0.01" ixy="0.0" ixz="0.0" iyy="0.01" iyz="0.0" izz="0.01"/>
    </inertial>
    <visual>
      <origin xyz="-0.02 0 0"/>
      <geometry>
        <box size="0.03 0.01995 0.005"/>
      </geometry>
      <material name="Green"/>
    </visual>
    <collision>
      <origin xyz="-0.02 0 0"/>
      <geometry>
        <box size="0.03 0.01995 0.005"/>
      </geometry>
    </collision>
  </link>
  <gazebo reference="front_right_bar_link">
    <material>Gazebo/Green</material>
  </gazebo>
  <!-- the front left wheel -->
  <joint name="front_left_wheel_joint" type="continuous">
    <axis xyz="0 1 0"/>
    <parent link="front_left_bar_link"/>
    <child link="front_left_wheel_link"/>
    <origin rpy="0 0 0" xyz="0 0.04 0"/>
  </joint>
  <link name="front_left_wheel_link">
    <inertial>
      <mass value="0.01"/>
      <origin xyz="0 0 0"/>
      <inertia ixx="0.01" ixy="0.0" ixz="0.0" iyy="0.01" iyz="0.0" izz="0.01"/>
    </inertial>
    <visual>
      <origin rpy="1.57079632679 0 0" xyz="0 0 0"/>
      <geometry>
        <cylinder length="0.025" radius="0.06"/>
      </geometry>
      <material name="Green"/>
    </visual>
    <collision>
      <origin rpy="1.57079632679 0 0" xyz="0 0 0"/>
      <geometry>
        <cylinder length="0.025" radius="0.06"/>
      </geometry>
    </collision>
  </link>
  <gazebo reference="front_left_wheel_link">
    <material>Gazebo/Green</material>
  </gazebo>
  <!-- the front right wheel -->
  <joint name="front_right_wheel_joint" type="continuous">
    <axis xyz="0 1 0"/>
    <parent link="front_right_bar_link"/>
    <child link="front_right_wheel_link"/>
    <origin rpy="0 0 0" xyz="0 -0.04 0"/>
  </joint>
  <link name="front_right_wheel_link">
    <inertial>
      <mass value="0.01"/>
      <origin xyz="0 0 0"/>
      <inertia ixx="0.01" ixy="0.0" ixz="0.0" iyy="0.01" iyz="0.0" izz="0.01"/>
    </inertial>
    <visual>
      <origin rpy="1.57079632679 0 0" xyz="0 0 0"/>
      <geometry>
        <cylinder length="0.025" radius="0.06"/>
      </geometry>
      <material name="Green"/>
    </visual>
    <collision>
      <origin rpy="1.57079632679 0 0" xyz="0 0 0"/>
      <geometry>
        <cylinder length="0.025" radius="0.06"/>
      </geometry>
    </collision>
  </link>
  <gazebo reference="front_right_wheel_link">
    <material>Gazebo/Green</material>
    <turnGravityOff>false</turnGravityOff>
  </gazebo>
  <!-- the Ackerman bar -->
  <joint name="ackermann_joint" type="revolute">
    <limit effort="100" lower="-0.5" upper="0.5" velocity="10"/>
    <axis xyz="0 0 1"/>
    <parent link="steer_link"/>
    <child link="ackermann_bar_link"/>
    <origin rpy="0 0 0" xyz="-0.04 0 0"/>
  </joint>
  <link name="ackermann_bar_link">
    <inertial>
      <mass value="0.01"/>
      <origin xyz="0 0 0"/>
      <inertia ixx="0.01" ixy="0.0" ixz="0.0" iyy="0.01" iyz="0.0" izz="0.01"/>
    </inertial>
    <visual>
      <geometry>
        <box size="0.015 0.15 0.01"/>
      </geometry>
      <material name="Green"/>
    </visual>
    <collision>
      <geometry>
        <box size="0.015 0.15 0.01"/>
      </geometry>
    </collision>
  </link>
  <gazebo reference="front_link">
    <material>Gazebo/Green</material>
  </gazebo>
  <gazebo reference="ackermann_bar_link">
    <material>Gazebo/Blue</material>
  </gazebo>
  <!-- Gazebo Ackermann loop joints -->
  <gazebo>
    <joint:hinge name="ackermann_left_bar_joint">
      <body1>ackermann_bar_link</body1>
      <body2>front_left_bar_link</body2>
      <anchor>ackermann_bar_link</anchor>
      <axis>0 0 1</axis>
      <anchorOffset>0 0.06 0</anchorOffset>
    </joint:hinge>
  </gazebo>
  <gazebo>
    <joint:hinge name="ackermann_right_bar_joint">
      <body1>ackermann_bar_link</body1>
      <body2>front_right_bar_link</body2>
      <anchor>ackermann_bar_link</anchor>
      <axis>0 0 1</axis>
      <anchorOffset>0 -0.06 0</anchorOffset>
    </joint:hinge>
  </gazebo>
  <!-- the back left wheel -->
  <joint name="back_left_wheel_joint" type="continuous">
    <axis xyz="0 1 0"/>
    <parent link="base_link"/>
    <child link="back_left_wheel_link"/>
    <origin rpy="0 0 0" xyz="-0.16 0.1 -0.1"/>
  </joint>
  <link name="back_left_wheel_link">
    <inertial>
      <mass value="0.01"/>
      <origin xyz="0 0 0"/>
      <inertia ixx="0.01" ixy="0.0" ixz="0.0" iyy="0.01" iyz="0.0" izz="0.01"/>
    </inertial>
    <visual>
      <origin rpy="1.57079632679 0 0" xyz="0 0 0"/>
      <geometry>
        <cylinder length="0.025" radius="0.06"/>
      </geometry>
      <material name="Black"/>
    </visual>
    <collision>
      <origin rpy="1.57079632679 0 0" xyz="0 0 0"/>
      <geometry>
        <cylinder length="0.025" radius="0.06"/>
      </geometry>
    </collision>
  </link>
  <gazebo reference="back_left_wheel_link">
    <material>Gazebo/Black</material>
  </gazebo>
  <!-- the back right wheel -->
  <joint name="back_right_wheel_joint" type="continuous">
    <axis xyz="0 1 0"/>
    <parent link="base_link"/>
    <child link="back_right_wheel_link"/>
    <origin rpy="0 0 0" xyz="-0.16 -0.1 -0.1"/>
  </joint>
  <link name="back_right_wheel_link">
    <inertial>
      <mass value="0.01"/>
      <origin xyz="0 0 0"/>
      <inertia ixx="0.01" ixy="0.0" ixz="0.0" iyy="0.01" iyz="0.0" izz="0.01"/>
    </inertial>
    <visual>
      <origin rpy="1.57079632679 0 0" xyz="0 0 0"/>
      <geometry>
        <cylinder length="0.025" radius="0.06"/>
      </geometry>
      <material name="Black"/>
    </visual>
    <collision>
      <origin rpy="1.57079632679 0 0" xyz="0 0 0"/>
      <geometry>
        <cylinder length="0.025" radius="0.06"/>
      </geometry>
    </collision>
  </link>
  <gazebo reference="back_right_wheel_link">
    <material>Gazebo/Black</material>
  </gazebo>
  <!-- Ackermann plugin -->
  <gazebo>
    <controller:ackermann_plugin name="ackermann_controller" plugin="libackermann_plugin.so">
      <alwaysOn>true</alwaysOn>
      <update>100</update>
      <updateRate>100.0</updateRate>
      <leftJoint>back_left_wheel_joint</leftJoint>
      <rightJoint>back_right_wheel_joint</rightJoint>
      <steerJoint>steer_joint</steerJoint>
      <wheelSeparationWidth>0.16</wheelSeparationWidth>
      <wheelSeparationLength>0.32</wheelSeparationLength>
      <wheelDiameter>0.041</wheelDiameter>
      <driveTorque>5</driveTorque>
      <steerTorque>5</steerTorque>
      <interface:position name="position_iface_0"/>
      <robotNamespace>/</robotNamespace>
      <topicName>pilot/drive</topicName>
    </controller:ackermann_plugin>
    <canonicalBody>base_footprint</canonicalBody>
    <!-- this publishes empty joint_states due to no transmission, but
    triggering robot_state_publisher to publish tf between fixed joints in erratic,
    (e.g. base_laser_link for the base_scan frame) -->
    <controller:gazebo_ros_controller_manager name="gazebo_ros_controller_manager" plugin="libgazebo_ros_controller_manager.so">
      <alwaysOn>true</alwaysOn>
      <updateRate>100.0</updateRate>
      <interface:audio name="gazebo_ros_controller_manager_dummy_iface"/>
    </controller:gazebo_ros_controller_manager>
  </gazebo>
  <joint name="laser_base_mount_joint" type="fixed">
    <origin rpy="0 0 0" xyz="0 0 0.05"/>
    <parent link="base_link"/>
    <child link="laser_base_link"/>
  </joint>
  <link name="laser_base_link" type="fixed">
    <inertial>
      <mass value="0.1"/>
      <origin xyz="0 0 0.0"/>
      <inertia ixx="0.1" ixy="0" ixz="0" iyy="0.1" iyz="0" izz="0.1"/>
    </inertial>
    <visual>
      <origin rpy="0 0 0" xyz="0 0 0.025"/>
      <geometry>
        <box size="0.05 0.05 0.05"/>
      </geometry>
    </visual>
    <collision>
      <origin rpy="0 0 0" xyz="0 0 0.025"/>
      <geometry>
        <box size="0.05 0.05 0.05"/>
      </geometry>
    </collision>
  </link>
  <joint name="base_scan_joint" type="fixed">
    <origin rpy="0 0 0" xyz="0 0 0.05"/>
    <parent link="laser_base_link"/>
    <child link="base_scan_link"/>
  </joint>
  <link name="base_scan_link" type="laser">
    <inertial>
      <mass value="0.1"/>
      <origin xyz="0 0 0.0"/>
      <inertia ixx="0.1" ixy="0" ixz="0" iyy="0.1" iyz="0" izz="0.1"/>
    </inertial>
    <visual>
      <origin rpy="0 0 0" xyz="0 0 0.014"/>
      <geometry>
        <cylinder length="0.028" radius="0.0229"/>
      </geometry>
    </visual>
    <collision>
      <origin rpy="0 0 0" xyz="0 0 0.014"/>
      <geometry>
        <cylinder length="0.028" radius="0.0229"/>
      </geometry>
    </collision>
  </link>
  <gazebo reference="base_scan_link">
    <sensor:ray name="laser">
      <rayCount>683</rayCount>
      <rangeCount>683</rangeCount>
      <laserCount>1</laserCount>
      <origin>0.0 0.0 0.0</origin>
      <displayRays>false</displayRays>
      <minAngle>-135</minAngle>
      <maxAngle> 135</maxAngle>
      <minRange>0.06</minRange>
      <maxRange>4.0</maxRange>
      <resRange>0.001</resRange>
      <updateRate>10.0</updateRate>
      <controller:gazebo_ros_laser name="gazebo_ros_base_scan_link_controller" plugin="libgazebo_ros_laser.so">
        <gaussianNoise>0.005</gaussianNoise>
        <alwaysOn>true</alwaysOn>
        <updateRate>10.0</updateRate>
        <topicName>base_scan/scan</topicName>
        <frameName>base_scan_link</frameName>
        <interface:laser name="gazebo_ros_base_scan_link_iface"/>
      </controller:gazebo_ros_laser>
    </sensor:ray>
  </gazebo>
  <gazebo reference="laser_base_link">
    <material>Gazebo/Black</material>
  </gazebo>
  <gazebo reference="base_scan_link">
    <material>Gazebo/Black</material>
  </gazebo>
</robot>
